#VRML_SIM V7.2.5 utf8
# omnidirectionnal wheel containing 6 passive motors
# Author: fabien.rohrer@cyberbotics.com

PROTO RealisticInteriorWheel [
  field SFVec3f translation 0 0 0
  field SFVec3f anchor 0 0 0
  field SFString name "wheel"
]
{
  HingeJoint {
    device RotationalMotor {
      name IS name
      maxVelocity 14.81
    }
    jointParameters HingeJointParameters {
      axis 0 1 0
      anchor IS anchor
    }
    endPoint Solid {
      translation IS translation
      children [
        WheelMesh {
        }
        Solid {
          translation 0 0 0.036
          rotation 0 0 1 0.785402
          children [
            SubWheel {
            }
          ]
          boundingObject DEF FAKE_BO Sphere {
            radius 0.01
          }
          physics DEF FAKE_PHYSICS Physics {
            density -1
            mass 0.05
          }
        }
        Solid {
          translation 0.0311 0 0.018
          rotation 0.318977 0.770074 0.552484 1.28666
          children [
            SubWheel {
            }
          ]
          boundingObject USE FAKE_BO
          physics USE FAKE_PHYSICS
        }
        Solid {
          translation 0.0311 0 -0.018
          rotation 0.373673 0.902122 0.21574 2.18123
          children [
            SubWheel {
            }
          ]
          boundingObject USE FAKE_BO
          physics USE FAKE_PHYSICS
        }
        Solid {
          translation 0 0 -0.036
          rotation 0.382685 0.923879 0 3.14159
          children [
            SubWheel {
            }
          ]
          boundingObject USE FAKE_BO
          physics USE FAKE_PHYSICS
        }
        Solid {
          translation -0.0311 0 -0.018
          rotation 0.373673 0.902122 -0.21574 4.10195
          children [
            SubWheel {
            }
          ]
          boundingObject USE FAKE_BO
          physics USE FAKE_PHYSICS
        }
        Solid {
          translation -0.0311 0 0.018
          rotation 0.318977 0.770074 -0.552484 4.99652
          children [
            SubWheel {
            }
          ]
          boundingObject USE FAKE_BO
          physics USE FAKE_PHYSICS
        }
      ]
      boundingObject Cylinder {
        height 0.072
        radius 0.047
        subdivision 24
      }
      physics Physics {
        density -1
        mass 0.4
      }
    }
  }
}
