#VRML_SIM V7.3.0 utf8
#############################################
# THOR-OP webots prototype file
# Based on Robotis wbt
# (c) Stephen McGill, 2014
#  Changes: variable knee torque (needed for terrain tasks)
#  Shrunk foot size according to actual robot
#  MINIMUM number of bounding box for speed up
#  SJ: cleaned-up all mass properties according thorIK.h
#  Fixed wrong arm lengths
# unlimited arm torque and velocity (for arm motion testing)
# Added inertia matrices for upper body
#############################################

PROTO THOROP_UPENN_Fullmass_nosensor [
  field SFVec3f    translation 0 1.155 0
  field SFRotation rotation 0 1 0 0
  field SFString   controller "void"
  field SFString   controllerArgs ""
  field SFBool     synchronization TRUE
	field SFFloat    lidarFov 3.1415926536
	field SFInt32    lidarRays 720
	#SJ - robotis rating is not enough to keep the robot standing
	field SFFloat    max_torque_400w 44
	field SFFloat    max_torque_200w 44
  field SFFloat    max_torque_100w 24

  # We may want wider FOV for head lidar	
  field SFString   name "THOR-OP"

  field SFString   footContactMaterial "default"
]
{
Robot {
  # General Characteristics
  translation IS translation
  rotation IS rotation
  synchronization IS synchronization
  name IS name
  controller IS controller
  controllerArgs IS controllerArgs
  description "Robotis THOR-OP"

 
  #Center of the robot is 170mm higher than the waist pitch joint  
  #################################################################
	boundingObject Transform {    
    translation 0 0 0
    children [Box {size 0.05 0.05 0.05}]
  }    
  physics Physics {
    density -1 
    mass 9.21
    centerOfMass [0 -0.0143 -0.0208]   # 0.1700-0.1557 = -0.0143
  }
  #################################################################  
  # Children items
  children [    

    DEF RECEIVER Receiver {
      name "receiver"
      channel IS channel
    }
    DEF EMITTER Emitter {
      name "emitter"
      channel IS channel
    }
    DEF PHYSICS_RECEIVER Receiver {
      name "physics_receiver"
      type "serial"
      channel 10
      byteSize 192
    }
    DEF PHYSICS_EMITTER Emitter {
      name "physics_emitter"
      type "serial"
      byteSize 96
    }
    ## End of sensors that are children of the root

		## The Chest is occupies the same position as the root
    CHEST{ scale 0.001 0.001 0.001 }
    ## End of chest this is root child


    ## Begin the Legs
    DEF Torso_pitch HingeJoint {
			device RotationalMotor {
				name "TorsoPitch"
				maxVelocity 2.9216811678
				maxTorque 44.2				
				minPosition -2.92343
				maxPosition 2.92343
			}
			jointParameters HingeJointParameters {
				axis 1 0 0
				anchor 0 -0.17 0
				dampingConstant 0.1                              
			}
			endPoint Solid {
				translation 0 -0.17 0
				#################################################################
				boundingObject Transform {    
    			translation 0 0 0
    			children [Box {size 0.05 0.05 0.05}]
  			}    
				physics Physics {density -1  mass 0.2} 				
				#################################################################
				children [
					TORSO_PITCH_SERVO {
						translation 0 -0.038 0
						scale 0.001 0.001 0.001
					}
					DEF Torso_yaw HingeJoint {
						device RotationalMotor {
							name "TorsoYaw"
							maxVelocity 2.9216811678
							maxTorque 44.2
							minPosition -3.14
							maxPosition 6.28
						}
						jointParameters HingeJointParameters {
							# Out x for pitch
							axis 0 1 0
							anchor 0 -0.038 0
							dampingConstant 0.1                              
						}
						endPoint Solid {
							translation 0 -0.050 0
							#translation 0 -0.038 0							
							#comPelvis = (-0.0264,0,-0.1208) based on waist pitch
							#################################################################
							boundingObject Transform {    
    						translation 0 -0.080 0
    						children [Box {size 0.05 0.05 0.05}]
  						}    							
							physics Physics {density -1 mass 8.0 
									centerOfMass [0 -0.0708 -0.0264]}
							#################################################################
							children [
								DEF Pelvis PELVIS {
									translation 0 -0.0875 0
									scale 0.001 0.001 0.001
								}

						    ## The sensors occupy the same position as the Chest
						    InertialUnit {name "InertialUnit"}
						    Compass {name "Compass"}
						    GPS {name "GPS"}
						    DEF ACCEL Accelerometer {
						      name "Accelerometer"
						      # Must place where is on the actual robot
						      translation 0 0 0.02
						      # Rotate to the correct orientation
						      rotation 0 0.707107 0.707107 3.14159
						      lookupTable [
						         -39.24 0 0
						         39.24 1024 0
						      ]
						    }
						    DEF GYRO Gyro {
						      # Must place where is on the actual robot
						      translation 0 0 0.02
						      # Rotate to the correct orientation
						      rotation -0.57735 0.57735 0.57735 2.09
						      name "Gyro"
						      lookupTable [
						         -27.925 0 0
						         27.925 1024 0
						      ]
						    }

								## Begin Right Leg
								DEF Right_hip_yaw HingeJoint {
									device RotationalMotor {
										name "PelvYR"
										maxVelocity 3.15 maxTorque IS max_torque_100w
										minPosition -2.92343 maxPosition 2.92343
									}
									jointParameters HingeJointParameters {
										axis 0 1 0
										anchor -0.072 -0.232 0
										dampingConstant 0.1                              
									}
									endPoint Solid {
										translation -0.072 -0.232 0
										boundingObject Transform {    
			    						translation 0 0.07 0
    									children [Box {size 0.05 0.05 0.05}]
  									}    				
										physics Physics {
											#################################################################
											density -1 mass 0.165
											centerOfMass [0 0 0]
											inertiaMatrix[0.000103125, 0.000103125, 0.000103125, 0,0,0]
											#################################################################
										}

										children[
											LEFT_HIP_YAW {
												translation 0 0.063 0
												scale 0.001 0.001 0.001
											}
											DEF Right_hip_roll HingeJoint {
												device RotationalMotor {
													name "PelvR"
													# TODO: Use NX Motor specs
													maxVelocity 2.9216811678 
													maxTorque IS max_torque_200w
													minPosition -2.92343 maxPosition 2.92343
												} # End of the PelvYR RotationalMotor
												jointParameters HingeJointParameters {
													# Out x for pitch
													axis 0 0 1
													dampingConstant 0.1                              
												} # End of the PelvYR HingeJointParameters
												endPoint Solid {
												#################################################################		
													boundingObject Transform {    
			    									translation 0 0.0 0
    												children [Box {size 0.05 0.05 0.05}]
  												}    				
                          physics Physics {density -1 mass 1.122
														centerOfMass [0 0 0]
 	                         inertiaMatrix[0.00070125, 0.00070125, 0.00070125, 0,0,0]
                          }
                        #################################################################
													children[
														HIP_ROLL {
															scale 0.001 0.001 0.001
														}
														DEF Right_hip_pitch HingeJoint {
															device RotationalMotor {
																name "LegUpperR"
																maxVelocity 2.9216811678 maxTorque IS max_torque_200w
																minPosition -2.92343 maxPosition 2.92343
															}
															jointParameters HingeJointParameters {
																axis 1 0 0
																dampingConstant 0.1                              
															}
															endPoint Solid {
																boundingObject Transform {    
			    												translation 0 -0.10 0
    															children [Box {size 0.05 0.05 0.05}]
  															}    				
                                physics Physics {
                                #################################################################
                                  density -1 mass 3.432																	
																	centerOfMass [-0.014 -0.130 -0.029]
																	inertiaMatrix[0.002145, 0.002145,0.002145, 0,0,0]
 	 												  		#################################################################
                                }
																
																children [
																	R_THIGH{
																		rotation 0 1 0 3.14159
																		scale 0.001 0.001 0.001
																	}
																	DEF Right_knee_pitch HingeJoint {
																		device RotationalMotor {
																			name "LegLowerR"
																			maxVelocity 2.9216811678
																			maxTorque IS max_torque_400w
																			minPosition -2.92343
																			maxPosition 2.92343
																		}
																		jointParameters HingeJointParameters {
																			axis 1 0 0
																			anchor 0 -0.3 -0.03
																			dampingConstant 0.1             
																		}
																		endPoint Solid {
																			translation 0 -0.3 -0.03
																			boundingObject Transform {
																				translation -0.025 -0.162 0.043
																				children [Box {size 0.144 0.29 0.085}]
																			}
                                      physics Physics {
                                      #################################################################
                                        density -1 mass 2.464                       
																				centerOfMass [-0.019 -0.119 0.031]
																				inertiaMatrix[0.00154,0.00154,0.00154, 0,0,0]
																			#################################################################
                                      }
																			children[
																				R_LEG{
																					translation 0 0 0.03
																					rotation 0 1 0 3.14159
																					scale 0.001 0.001 0.001
																				}
																				DEF Right_ankle_pitch HingeJoint {
																					device RotationalMotor {
																						name "AnkleR"
																						maxVelocity 2.9216811678
																						maxTorque IS max_torque_200w
																						minPosition -2.92343
																						maxPosition 2.92343
																					} # End of the LegLowerR RotationalMotor
																					jointParameters HingeJointParameters {
																						axis 1 0 0
																						anchor 0 -0.3 0.03
																						dampingConstant 0.1             
																					}
																					endPoint Solid {
																						translation 0 -0.3 0.03
                                            contactMaterial IS footContactMaterial
                                            #########################################################
                                            boundingObject Transform {    
			    																		translation 0 0.0 0
    																					children [Box {size 0.03 0.03 0.03}]
  																					}    				
																						physics Physics {density -1 
																							mass 0.946
																							centerOfMass [0 0 0]
																							inertiaMatrix[0.00059125,0.00059125,0.00059125, 0,0,0]
																							}
																						#################################################################
																						children[
																							LEFT_ANKLE {
																								scale 0.001 0.001 0.001
																							}
																							DEF Right_ankle_roll HingeJoint {
																								device RotationalMotor {
																									name "FootR"
																									maxVelocity 3.1520646292
																									maxTorque IS max_torque_100w		
																									minPosition -2.92343 maxPosition 2.92343
																								} # End of the LegLowerR RotationalMotor
																								jointParameters HingeJointParameters {
																									axis 0 0 1
																									dampingConstant 0.1             
																									}
																								endPoint Solid {
                                                	contactMaterial IS footContactMaterial															
																									####################################################	
																										boundingObject Transform {    
				    																					translation 0 0.0 0
	    																								children [Box {size 0.03 0.03 0.03}]
	  																								} 
	  																								physics Physics {density -1 

	  																									mass 0.2 #temp hack
	  																									centerOfMass [0 -0.031 0]
	  																									inertiaMatrix[0.000125,0.000125,0.000125, 0,0,0]
	  																								}
																									########################################################
																									children [
																										#FOOT {scale 0.001 0.001 0.001}
																										Transform{
																											translation 0 0 -0.005
																											children[FOOT {scale 0.001 0.001 0.000923}]
																										}																										
                                                    DEF Right_ankle_force TouchSensor { 
                                                      lookupTable   [ 0 0 0, 5000 5000 0 ]
                                                      name "RAnkle_force"
                                                      contactMaterial IS footContactMaterial
                                                      boundingObject Transform {            
                                                        translation 0 -0.093 0.01
                                                        children [               
                                                          Box {size 0.147 0.05 0.240}
                                                        ]
                                                      }
                                                     	physics Physics {
                                                     		#we consider the mass of force sensor...
                                             	    			#density -1 mass 1.133
                                                  			density -1 mass 0.933
                                                  			centerOfMass [0 -0.031 0]
                                                  			inertiaMatrix[0.000583125,0.000583125,0.000583125, 0,0,0]
                                                  		}
                                                      type "force-3d"                                                    
                                                    }

																									]
																								}
																							}
																						]
																					}
																				}
																			]
																		}
																	}
																]
															}
														}
													]
												}
											}
										]
									}
								}
								## End Right Leg

								## Begin  Left Leg
								DEF Left_hip_yaw HingeJoint {
									device RotationalMotor {
										name "PelvYL"
										maxVelocity 3.15 maxTorque IS max_torque_100w
										minPosition -2.92343 maxPosition 2.92343
									}
									jointParameters HingeJointParameters {
										axis 0 1 0
										anchor 0.072 -0.232 0
										dampingConstant 0.1
									}
									endPoint Solid {
										translation 0.072 -0.232 0
										boundingObject Transform {    
			    						translation 0 0.07 0
    									children [Box {size 0.05 0.05 0.05}]
  									}    				
										physics Physics {
										##############################################################
											density -1 mass 0.165
											centerOfMass [0 0 0]
											inertiaMatrix[0.000103125, 0.000103125, 0.000103125, 0,0,0]
										##############################################################
										}
									
										children[
											LEFT_HIP_YAW {
												translation 0 0.063 0
												scale 0.001 0.001 0.001
											}
											DEF Left_hip_roll HingeJoint {
												device RotationalMotor {
													name "PelvL"
													maxVelocity 2.9216811678
													maxTorque IS max_torque_200w
													minPosition -2.92343 maxPosition 2.92343
												}
												jointParameters HingeJointParameters {
													# Out x for pitch
													axis 0 0 1
													dampingConstant 0.1                              
												}
												endPoint Solid {
												##############################################################
												boundingObject Transform {    
			    									translation 0 0.0 0
    												children [Box {size 0.05 0.05 0.05}]
  												}    				
                          physics Physics {
                          	density -1 mass 1.122
                          	centerOfMass [0 0 0]
                          	inertiaMatrix[0.00070125, 0.00070125, 0.00070125, 0,0,0]
                          	}
	                      ##############################################################
													children[
														HIP_ROLL {
															scale 0.001 0.001 0.001
														}
														DEF Left_hip_pitch HingeJoint {
															device RotationalMotor {
																name "LegUpperL"
																maxVelocity 2.9216811678
																maxTorque IS max_torque_200w
																minPosition -2.92343 maxPosition 2.92343
															}
															jointParameters HingeJointParameters {
																axis 1 0 0
																dampingConstant 0.1        
															}
															endPoint Solid {
																boundingObject Transform {    
			    												translation 0 -0.10 0
    															children [Box {size 0.05 0.05 0.05}]
  															}    				
																physics Physics {
															##############################################################
                                density -1 mass 3.432																	
																	centerOfMass [0.014 -0.130 -0.029]
																	inertiaMatrix[0.002145, 0.002145,0.002145, 0,0,0]                        
															##############################################################
																}
																children [
																	L_THIGH{
																		#rotation 0 1 0 3.14159
																		scale 0.001 0.001 0.001
																	}
																	DEF  Left_knee_pitch HingeJoint {
																		device RotationalMotor {
																			name "LegLowerL"
																			maxVelocity 2.9216811678
																			maxTorque IS max_torque_400w																		
																			minPosition -2.92343 maxPosition 2.92343
																		}
																		jointParameters HingeJointParameters {
																			axis 1 0 0
																			anchor 0 -0.3 -0.03
																			dampingConstant 0.1             
																		}
																		endPoint Solid {
																			translation 0 -0.3 -0.03
																			boundingObject Transform {
																			#higher shin bounding box
																				#translation 0.025 -0.192 0.043
																				#children [Box {size 0.144 0.35 0.085}]
																				translation 0.025 -0.162 0.043
																				children [Box {size 0.144 0.29 0.085}]
																			}
                                      physics Physics {
                                      ##############################################################
                                      density -1 mass 2.464
																				centerOfMass [0.019 -0.119 0.031]
																				inertiaMatrix[0.00154,0.00154,0.00154, 0,0,0]
																			##############################################################
                                      }
																			children[
																				L_LEG{
																					translation 0 0 0.03
																					#rotation 0 1 0 3.14159
																					scale 0.001 0.001 0.001
																				}
																				DEF Left_ankle_pitch HingeJoint {
																					device RotationalMotor {
																						name "AnkleL"
																						maxVelocity 2.9216811678
																						maxTorque IS max_torque_200w																	
																						minPosition -2.92343 maxPosition 2.92343
																					} # End of the LegLowerR RotationalMotor
																					jointParameters HingeJointParameters {
																						axis 1 0 0
																						anchor 0 -0.3 0.03
																					} # End of the LegLowerR HingeJointParameters
																					endPoint Solid {
																						translation 0 -0.3 0.03
                                            contactMaterial IS footContactMaterial
																				##############################################################
																						boundingObject Transform {    
			    																		translation 0 0.0 0
    																					children [Box {size 0.03 0.03 0.03}]
  																					}    				
																						physics Physics {
																							density -1 mass 0.946
																							inertiaMatrix[0.00059125,0.00059125,0.00059125, 0,0,0]
																							centerOfMass [0 0 0]
																						}
																			  ##############################################################
																						children[
																							LEFT_ANKLE {
																								scale 0.001 0.001 0.001
																							}
																							DEF Left_ankle_roll HingeJoint {
																								device RotationalMotor {
																									name "FootL"
																									maxVelocity 3.1520646292
																									maxTorque IS max_torque_100w
																									minPosition -2.92343 maxPosition 2.92343
																								}
																								jointParameters HingeJointParameters {
																									axis 0 0 1
																									}
																								endPoint Solid {
                                                  contactMaterial IS footContactMaterial
																					########################################################						
																									boundingObject Transform {    
			    																					translation 0 0.0 0
    																								children [Box {size 0.03 0.03 0.03}]
  																								}    				
                                                  physics Physics {density -1 mass 0.2
                                                  	centerOfMass [0 -0.031 0]
                                                  	inertiaMatrix[0.000125,0.000125,0.000125, 0,0,0]
                                                  }
																						########################################################
																									children [
																										#FOOT {scale 0.001 0.001 0.001}
																										Transform{
																											translation 0 0 -0.005
																											children[FOOT {scale 0.001 0.001 0.000923}]
																										}
																										
                                                    DEF Left_ankle_force TouchSensor {
                                                      lookupTable   [ 0 0 0, 5000 5000 0 ]
                                                      name "LAnkle_force"
                                                      contactMaterial IS footContactMaterial    
                                                      boundingObject Transform {
                                                          translation 0 -0.093 0.010
                                                          children [
                                                            Box {
                                                              size 0.147 0.05 0.240
                                                            }
                                                          ]
                                                        }                                                 
                                                  		physics Physics {
                                                  			#sj - we have to consider the mass of touchsensor
                                                  			#density -1 mass 1.133
                                                  			density -1 mass 0.933
                                                  			centerOfMass [0 -0.031 0]
                                                  			inertiaMatrix[0.000583125,0.000583125,0.000583125, 0,0,0]
                                                  		}
                                                      type "force-3d"
                                                    }
      																						
																									]
																								}
																							}
																						]
																					}
																				}
																			]
																		}
																	}
																]
															}
														}
													]
												}
											}
										]
									}
								}
								# End Left Leg






						]
						}
					}
				]
			}
		}
		## End the Legs




## Begin the Right arm chain
    DEF Right_shoulder_pitch HingeJoint {
      device RotationalMotor {
        name "ShoulderR"
        maxVelocity 2.9216811678
				maxTorque 44.2
        minPosition -2.92343 maxPosition 2.92343
      } # End of the ShoulderR RotationalMotor
      jointParameters HingeJointParameters {
        axis 1 0 0
        anchor -0.234 0 0
        dampingConstant 0.1                              
      } # End of the ShoulderR HingeJointParameters
      endPoint Solid {
        translation -0.234 0 0
        ##############################################################
        boundingObject Transform {
        	translation 0.10 0 0
          children [Box {size 0.05 0.05 0.05}]
        }        		
        physics Physics {
        	density -1 
        	mass 0.1
          centerOfMass 0 0.0 0
      	  inertiaMatrix[0.0000625, 0.0000625, 0.0000625, 0,0,0]
      	}
        ##############################################################		
        children [
          RIGHT_SHOULDER_PITCH {
            scale 0.001 0.001 0.001
            translation 0.05 0 0
            rotation 0 0 1 -1.5708
          }
          DEF Right_shoulder_roll HingeJoint {
            device RotationalMotor {
              name "ArmUpperR"
              maxVelocity 2.9216811678
							maxTorque 44.2              
              minPosition -2.92343 maxPosition 2.92343
            } # End of the ArmUpperR RotationalMotor
            jointParameters HingeJointParameters {
              axis 0 0 -1
              dampingConstant 0.1                            
            } # End of the ArmUpperR HingeJointParameters
            endPoint Solid {
            #########################################################
              boundingObject Transform {	          		
          			translation 0.01 0 0
          			children [Box {size 0.085 0.066 0.15}]
        			}         		
              physics Physics {
              	density -1 mass 2.89
                centerOfMass 0 -0.1027 -0.008
                inertiaMatrix[0.00180625, 0.00180625, 0.00180625, 0,0,0]
              }
 				 ##############################################################
              ## Begin Shoulder Yaw
              children [
                SHOULDER_ROLL{
                  scale 0.001 0.001 0.001
                  translation 0 0 0.024
                  #rotation 0 0 1 -1.5708
                }
                DEF Right_shoulder_yaw HingeJoint {
                  device RotationalMotor {
                    name "RightShoulderYaw"
                    maxVelocity 2.9216811678
										maxTorque 44.2                    
                    minPosition -2.92343 maxPosition 2.92343
                  }
                  jointParameters HingeJointParameters {
                    axis 0 1 0
                     dampingConstant 0.1                    
                  }
                  endPoint Solid {
              ########################################################
										boundingObject Transform {
	          					translation 0 -0.07 0
          						children [Box {size 0.05 0.05 0.05}]
        						}
                    physics Physics {
                 			density -1 mass 0.13
                			centerOfMass 0 -0.246 0.030
                			inertiaMatrix[0.00008125, 0.00008125, 0.00008125, 0,0,0]
                		}
				#############################################################
                    children [
  										RIGHT_ARM{
  											translation 0 -0.027 0
  											rotation 0 1 0 3.14159
  											scale 0.001 0.001 0.001
  										}
                      DEF Right_elbow_pitch HingeJoint {
                        device RotationalMotor {
                          name "ArmLowerR"
                          maxVelocity 3.1520646292
													maxTorque 24.8                          
                          minPosition -2.92343 maxPosition 2.92343
                        }
                        jointParameters HingeJointParameters {
                          axis -1 0 0
                          anchor 0 -0.246 0.030
                          dampingConstant 0.1                                                    
                        }
                        endPoint Solid {
                          translation 0 -0.246 0.030
                          ##############################################################		                    
                          boundingObject Transform {
        							      rotation 1 0 0 0.7854
                            children [Box {size 0.13 0.065 0.065}]
        									}
                          physics Physics {
                            density -1 
                            mass 0.81
                            centerOfMass 0 -0.0464 0
                            inertiaMatrix[0.00050625,0.00050625, 0.00050625, 0,0,0]
                          }
                          ##############################################################		
                          
                          children [
														RIGHT_ELBOW_LONG {translation 0 -0.125 -0.03}
                            DEF Right_wrist_yaw HingeJoint {
                              device RotationalMotor {
                                name "RightWristYaw"
                                maxVelocity 3.1206487025
                                maxTorque 6.3
                              } # End of the RightWristYaw RotationalMotor
                              jointParameters HingeJointParameters {                              
                                axis 0 1 0
																#anchor 0 -0.216 -0.03
																anchor 0 -0.25 -0.03
                                dampingConstant 0.1																			
                              } # End of the RightWristYaw HingeJointParameters
                              endPoint Solid {
                                translation 0 -0.250 -0.03
                                #############################################################	                                                   
																boundingObject Transform {
	          											translation 0 0.065 0
          												children [Box {size 0.05 0.05 0.05}]
        												}
                                physics Physics {
                                	density -1 
                                	mass 0.97
                                	centerOfMass 0 0.040 0
                                	inertiaMatrix[0.00060625,0.00060625, 0.00060625, 0,0,0]     	
                                }
                                #############################################################	                                                   
                                children [
                                  DEF Right_wrist_roll HingeJoint {
                                    device RotationalMotor {
                                      name "RightWristRoll"
                                      maxVelocity 3.1206487025
																			maxTorque 6.3
                                      minPosition -2.92343 maxPosition 2.92343
                                    } # End of the RightWristRoll RotationalMotor
                                    jointParameters HingeJointParameters {
                                      # Straight out the z axis
                                      #fixed
                                      axis 0 0 -1
                                      dampingConstant 0.1
                                    } # End of the RightWristRoll HingeJointParameters
                                    endPoint Solid {
                                    	translation 0 0 0 
                                	 ##############################################################	
                                      boundingObject Box { size 0.05 0.05 0.1 }
																		  physics Physics {
                                      	density -1
                                      	mass 0.1
                                      	centerOfMass 0 0 0
                                      	inertiaMatrix[0.0000625,0.0000625,0.0000625, 0,0,0]     
                                      }           
 				##############################################################	                                      
                                      children [
																				WRIST {
                                      		translation 0 0 0
                                      		scale 0.001 0.001 0.001}
        																WRIST {
        																	translation 0 -0.0650 0
        																	scale 0.001 0.001 0.001
                                          rotation 1 0 0 1.5708
        																}
                                        DEF Right_wrist_yaw2 HingeJoint {
                                          device RotationalMotor {
                                            name "RightWristYaw2"
                                            maxVelocity 3.1206487025
																						maxTorque 6.3
                                          }
                                          jointParameters HingeJointParameters {
                                          	#fixed
                                            axis 0 -1 0
                                            dampingConstant 0.1     
                                          }
#                                          endPoint CHOPSTICKS {translation 0 -0.05 0}

                                    endPoint Solid {
					                            translation 0 -0.095 0
					                            boundingObject Box { size 0.05 0.05 0.05 }
					                           	physics Physics{
					                           		density -1
					                           		mass 0.1
					                           		centerOfMass 0 0.0 0
					                           		inertiaMatrix[0.0000625,0.0000625,0.0000625, 0,0,0]     	
					                              }
					                    			}

#																			endPoint GRIPPER {
#																					translation 0 -0.075 0
#		  																			rotation 0 0 -1 0.707																		#
#																					trigger_name "r_trigger
#																					grip_name "r_grip"
#																				}

                                        } # End of the Wrist Yaw2 HingeJoint
                                      ] # End the solid children
                                      ## End Wrist Yaw2
                                    } # End of the Wrist Roll endpoint
                                  } # End of the Wrist Roll HingeJoint
                                ] # End the solid children
                                ## End Wrist Roll
                              } # End of the Wrist Yaw endpoint
                            } # End of the Wrist Yaw HingeJoint
                          ] # End the solid children
                          ## End Wrist Yaw
                        } # End of the Elbow endpoint
                      } # End of the Elbow HingeJoint
                    ] # End the solid children
                    ## End Elbow
                  } # End of the Shoulder Yaw endpoint
                } # End of the Shoulder Yaw HingeJoint
              ] # End the solid children
              ## End Shoulder Yaw
            } # End of the Shoulder Roll endpoint
          } # End of the Shoulder Roll HingeJoint
        ] # End the solid children
        ## End Shoulder Roll
      } # End of the Shoulder Pitch endpoint
    } # End of the Shoulder Pitch HingeJoint
## End the right arm chain





## Begin the Left arm chain
    DEF Left_shoulder_pitch HingeJoint {
      device RotationalMotor {
        name "ShoulderL"
        maxVelocity 2.9216811678
				maxTorque 44.2        
        minPosition -2.92343 maxPosition 2.92343
      }
      jointParameters HingeJointParameters {
        axis 1 0 0
        anchor -0.234 0 0
        dampingConstant 0.1                      
      }
      endPoint Solid {
        translation 0.234 0 0
        ##############################################################		
        boundingObject Transform {
        	translation -0.10 0 0
          children [Box {size 0.05 0.05 0.05}]
          
        }        
        physics Physics {
        	density -1          
        	mass 0.1
        	#Ixx = m/12*(s_y^2+s_z^2) for cuboid
        	#for 5cm*5cm*5cm body, Ixx = m/1600
        	#inertiaMatrix[I11 I22 I33, I12 I13 I23]
        	centerOfMass 0 0.0 0
        	inertiaMatrix[0.0000625, 0.0000625, 0.0000625, 0,0,0]

        }
        ##############################################################		
        children [
          LEFT_SHOULDER_PITCH {
            scale 0.001 0.001 0.001
            translation -0.05 0 0
            rotation 0 0 1 1.5708
          }
          DEF Left_shoulder_roll HingeJoint {
            device RotationalMotor {
              name "ArmUpperL"
              maxVelocity 2.9216811678
							maxTorque 44.2              
              minPosition -2.92343 maxPosition 2.92343
            }
            jointParameters HingeJointParameters {
              axis 0 0 -1
             dampingConstant 0.1              
#             dampingConstant 0              
              staticFriction 0
            }
            endPoint Solid {
            ##############################################################		
            	boundingObject Transform {	          		
          			translation -0.01 0 0
          			children [Box {size 0.085 0.066 0.15}]
        			}              
              physics Physics {
              	density -1 mass 2.89
                centerOfMass 0 -0.1027 -0.008 #this assumes straight down arm posture
                inertiaMatrix[0.00180625, 0.00180625, 0.00180625, 0,0,0]
              }
              ##############################################################		
              ## Begin Shoulder Yaw
              children [
                SHOULDER_ROLL {
                  scale 0.001 0.001 0.001
                  translation 0 0 0.024
                  #rotation 0 0 1 -1.5708
                }
                DEF Left_shoulder_yaw HingeJoint {
                  device RotationalMotor {
                    name "LeftShoulderYaw"
                    maxVelocity 2.9216811678
										maxTorque 44.2
                    minPosition -2.92343
                    maxPosition 2.92343
                  }
                  jointParameters HingeJointParameters {
                    axis 0 1 0
                    dampingConstant 0.1                                  
                  }
                  endPoint Solid {
                  	##############################################################		
										boundingObject Transform {
	          					translation 0 -0.07 0
          						children [Box {size 0.05 0.05 0.05}]
        						}  						     
                    physics Physics {
                    	density -1 mass 0.13
                    	centerOfMass 0 -0.246 0.030
                    	inertiaMatrix[0.00008125, 0.00008125, 0.00008125, 0,0,0]
                    }  
                    ##############################################################		                    
                    children [
  										LEFT_ARM {
  											translation 0 -0.027 0
  											#rotation 0 1 0 3.14159
  											scale 0.001 0.001 0.001
  										}									    
                      DEF Left_elbow_pitch HingeJoint {
                        device RotationalMotor {
                          name "ArmLowerL"
                          maxVelocity 3.1520646292
													maxTorque 24.8                          
                          minPosition -2.92343 maxPosition 2.92343
                        }
                        jointParameters HingeJointParameters {
                          axis 1 0 0
                          anchor 0 -0.246 0.030
                          dampingConstant 0.1                          
#              						dampingConstant 0              
              						staticFriction 0                          
                        }
                        endPoint Solid {
                          translation 0 -0.246 0.030
                          ##############################################################		                    
                          boundingObject Transform {
        							      rotation 1 0 0 0.7854
                            children [Box {size 0.13 0.065 0.065}]
        									}
                          physics Physics {
                            density -1 
                            mass 0.81
                            centerOfMass 0 -0.0464 0
                            inertiaMatrix[0.00050625,0.00050625, 0.00050625, 0,0,0]
                          }
                          ##############################################################		                    
                          children [
														RIGHT_ELBOW_LONG {
															translation 0 -0.125 -0.03												
														}
                            DEF Left_wrist_yaw HingeJoint {
                              device RotationalMotor {
                                name "LeftWristYaw"
                                maxVelocity 3.1206487025
                                maxTorque 6.3
                              } # End of the LeftWristYaw RotationalMotor
                              jointParameters HingeJointParameters {
                              	#fixed
                                axis 0 1 0
																anchor 0 -0.25 -0.03
                                dampingConstant 0.1																
                              } # End of the LeftWristYaw HingeJointParameters
                              endPoint Solid {                                
                                translation 0 -0.25 -0.03 #lower arm length is 250mm
				#############################################################	                                                   
                                boundingObject Transform {
	          											translation 0 0.065 0
          												children [Box {size 0.05 0.05 0.05}]
        												}
                                physics Physics {
                                	density -1 
                                	mass 0.97                                	
                                	centerOfMass 0 0.040 0
                           				inertiaMatrix[0.00060625,0.00060625, 0.00060625, 0,0,0]     	
                                }
	##############################################################		                                                    
                                children [
                                  DEF Left_wrist_roll HingeJoint {
                                    device RotationalMotor {
                                      name "LeftWristRoll"
                                      maxVelocity 3.1206487025
																			maxTorque 6.3                                      
                                      minPosition -2.92343 maxPosition 2.92343

                                    } # End of the LeftWristRoll RotationalMotor
                                    jointParameters HingeJointParameters {
                                      # Straight out the z axis
                                      axis 0 0 -1
                                      dampingConstant 0.1                                      
                                    } # End of the LeftWristRoll HingeJointParameters
                                    endPoint Solid {                                    	
                                      translation 0 0 0 
                                      ##############################################################		    
                                      boundingObject Box { size 0.05 0.05 0.1 }
																		  physics Physics {
                                      	density -1
                                      	mass 0.1
                                      	centerOfMass 0 0.0 0
                                      	inertiaMatrix[0.0000625,0.0000625,0.0000625, 0,0,0]     	
                                      }                                      
                                      ##############################################################
                                      children [
                                      	WRIST {
                                      		translation 0 0 0
                                      		scale 0.001 0.001 0.001}
        																WRIST {
        																	translation 0 -0.0650 0
        																	scale 0.001 0.001 0.001
                                          rotation 1 0 0 1.5708
        																}
                                        DEF Left_wrist_yaw2 HingeJoint {
                                          device RotationalMotor {
                                            name "LeftWristYaw2"
                                            maxVelocity 3.1206487025
																						maxTorque 6.3
                                          }
                                          jointParameters HingeJointParameters {
                                            axis 0 -1 0
																						dampingConstant 0.1                                            
                                          }
																					#endPoint GRIPPER_PLATE {translation 0 -0.05 0}
																					#endPoint CHOPSTICKS {translation 0 -0.05 0}
#                                          endPoint GRIPPER {
#                                            #translation 0 -0.05 0
#                                            translation 0 -0.095 0
#																						rotation 0 0 -1 0.707
#																						trigger_name "l_trigger"
#																						grip_name "l_grip"
#																					}

													endPoint Solid {
                            translation 0 -0.095 0
                            ##############################################################		    
                            boundingObject Box { size 0.05 0.05 0.05 }
                           	physics Physics{
                           		density -1
                           		mass 0.1
                           		centerOfMass 0 0 0
               		          	inertiaMatrix[0.0000625,0.0000625,0.0000625, 0,0,0]     	
                              }
                            ##############################################################		    
                    			}




                                        } # End of the Wrist Yaw2 HingeJoint
                                      ] # End the solid children
                                      ## End Wrist Yaw2
                                    } # End of the Wrist Roll endpoint
                                  } # End of the Wrist Roll HingeJoint
                                ] # End the solid children
                                ## End Wrist Roll
                              } # End of the Wrist Yaw endpoint
                            } # End of the Wrist Yaw HingeJoint
                          ] # End the solid children
                          ## End Wrist Yaw
                        } # End of the Elbow endpoint
                      } # End of the Elbow HingeJoint
                    ] # End the solid children
                    ## End Elbow
                  } # End of the Shoulder Yaw endpoint
                } # End of the Shoulder Yaw HingeJoint
              ] # End the solid children
              ## End Shoulder Yaw
            } # End of the Shoulder Roll endpoint
          } # End of the Shoulder Roll HingeJoint
        ] # End the solid children
        ## End Shoulder Roll
      } # End of the Shoulder Pitch endpoint
    } # End of the Shoulder Pitch HingeJoint
## End the left arm chain

  ] # End of the Robot children

} # End of Robot

} # End of PROTO
