<?xml version='1.0'?>
<sdf version="1.3">
<model name="ash_lowerbody">
	<plugin name="gz_comms_manager" filename="libgz_comms_manager.so" />
	<pose>0 0 0 0 0 0</pose>
	<static>false</static>
	<link name="torso">
		<pose>-.01 0 .997 0 0 0</pose>
		<collision name="collision">
			<geometry>
				<box>
					<size>.143 .114 .367</size>
				</box>
			</geometry>
		</collision>
		<visual name="visual">
			<geometry>
				<box>
					<size>.143 .114 .367</size>
				</box>
			</geometry>
		</visual>
		<inertial>
			<!-- <pose>-0.017635463 0.000532902 1.008170676 0 0 0</pose> -->
			<pose>-0.007635463 0.000532902 0.011170676 0 0 0</pose>
			<mass>8.929601491</mass>
			<inertia>
				<ixx>0.160370285</ixx>
				<iyy>0.112425821</iyy>
				<izz>0.106598912</izz>
				<iyz>0.000392533</iyz>
				<ixz>-0.002028322</ixz>
				<ixy>0.000446463</ixy>
			</inertia>
		</inertial>
		<sensor name="imu_sensor" type="imu">
			<visualize>1</visualize>
			<topic>imu_sensor</topic>
		</sensor>
	</link>


	<link name="l_thigh">
		<pose>-.021 .094 .618 0 0 0</pose>
		<collision name="collision">
			<geometry>
				<box>
					<size>.05 .05 .419</size>
				</box>
			</geometry>
		</collision>
		<visual name="visual">
			<geometry>
				<box>
					<size>.05 .05 .419</size>
				</box>
			</geometry>
		</visual>
		<inertial>
			<!-- <pose>-0.032097569 0.112874678 0.650768668 0 0 0</pose> -->
			<pose>-0.011097569 0.018874678 0.032768668 0 0 0</pose>
			<mass>2.298881991</mass>
			<inertia>
				<ixx>0.021768307</ixx>
				<iyy>0.024906869</iyy>
				<izz>0.008717440</izz>
				<iyz>-0.001607937</iyz>
				<ixz>-0.001277535</ixz>
				<ixy>-0.002003306</ixy>
			</inertia>
		</inertial>
	</link>

	<link name="r_thigh">
		<pose>-.021 -.094 .618 0 0 0</pose>
		<collision name="collision">
			<geometry>
				<box>
					<size>.05 .05 .419</size>
				</box>
			</geometry>
		</collision>
		<visual name="visual">
			<geometry>
				<box>
					<size>.05 .05 .419</size>
				</box>
			</geometry>
		</visual>
		<inertial>
			<!-- <pose>-0.032097569 -0.112874678 0.650768668 0 0 0</pose> -->
			<pose>-0.011097569 -0.018874678 0.032768668 0 0 0</pose>
			<mass>2.298881991</mass>
			<inertia>
				<ixx>0.021768307</ixx>
				<iyy>0.024906869</iyy>
				<izz>0.008717440</izz>
				<iyz>0.001607937</iyz>
				<ixz>-0.001277535</ixz>
				<ixy>0.002003306</ixy>
			</inertia>
		</inertial>
	</link>


	<link name="l_shin">
		<pose>-.021 .094 .239 0 0 0</pose>
		<collision name="collision">
			<geometry>
				<box>
					<size>.044 .044 .42</size>
				</box>
			</geometry>
		</collision>
		<visual name="visual">
			<geometry>
				<box>
					<size>.044 .044 .42</size>
				</box>
			</geometry>
		</visual>
		<inertial>
			<!-- <pose>-0.049153381 0.096475222 0.302721119 0 0 0</pose> -->
			<pose>-0.028153381 0.002475222 0.063721119 0 0 0</pose>
			<mass>2.239063829</mass>
			<inertia>
				<ixx>0.021743467</ixx>
				<iyy>0.027022394</iyy>
				<izz>0.010582813</izz>
				<iyz>-0.000035631</iyz>
				<ixz>0.004888637</ixz>
				<ixy>0.000055998</ixy>
			</inertia>
		</inertial>
	</link>

	<link name="r_shin">
		<pose>-.021 -.094 .239 0 0 0</pose>
		<collision name="collision">
			<geometry>
				<box>
					<size>.044 .044 .42</size>
				</box>
			</geometry>
		</collision>
		<visual name="visual">
			<geometry>
				<box>
					<size>.044 .044 .42</size>
				</box>
			</geometry>
		</visual>
		<inertial>
			<!-- <pose>-0.049153381 -0.096475222 0.302721119 0 0 0</pose> -->
			<pose>-0.028153381 -0.002475222 0.063721119 0 0 0</pose>
			<mass>2.239063829</mass>
			<inertia>
				<ixx>0.021743467</ixx>
				<iyy>0.027022394</iyy>
				<izz>0.010582813</izz>
				<iyz>-0.000035631</iyz>
				<ixz>0.004888637</ixz>
				<ixy>0.000055998</ixy>
			</inertia>
		</inertial>
	</link>


	<link name="l_foot">
		<pose>0 .094 .003 0 0 0</pose>
		<collision name="collision">
			<geometry>
				<box>
					<size>.23 .125 .006</size>
				</box>
			</geometry>
			<!-- From atlas model -->
			<surface>
				<friction>
					<ode>
						<mu>0.9</mu>
						<mu2>0.9</mu2>
						<fdir1>1 0 0</fdir1>
					</ode>
				</friction>
				<contact>
					<ode>
						<max_vel>1.0</max_vel>
						<min_depth>0.003</min_depth>
					</ode>
				</contact>
			</surface>
		</collision>
		<visual name="visual">
			<geometry>
				<box>
					<size>.23 .125 .006</size>
				</box>
			</geometry>
		</visual>
		<inertial>
			<!-- <pose>-0.019883971 0.096275946 0.019387485 0 0 0</pose> -->
			<pose>-0.019883971 0.002275946 0.016387485 0 0 0</pose>
			<mass>0.589284444</mass>
			<inertia>
				<ixx>0.000545429</ixx>
				<iyy>0.001825441</iyy>
				<izz>0.002054387</izz>
				<iyz>-0.000001187</iyz>
				<ixz>-0.000179602</ixz>
				<ixy>0.000004512</ixy>
			</inertia>
		</inertial>
	</link>

	<link name="r_foot">
		<pose>0 -.094 .003 0 0 0</pose>
		<collision name="collision">
			<geometry>
				<box>
					<size>.23 .125 .006</size>
				</box>
			</geometry>
			<!-- From atlas model -->
			<surface>
				<friction>
					<ode>
						<mu>0.9</mu>
						<mu2>0.9</mu2>
						<fdir1>1 0 0</fdir1>
					</ode>
				</friction>
				<contact>
					<ode>
						<max_vel>1.0</max_vel>
						<min_depth>0.003</min_depth>
					</ode>
				</contact>
			</surface>
		</collision>
		<visual name="visual">
			<geometry>
				<box>
					<size>.23 .125 .006</size>
				</box>
			</geometry>
		</visual>
		<inertial>
			<!-- <pose>-0.019883971 -0.096275946 0.019387485 0 0 0</pose> -->
			<pose>-0.019883971 -0.002275946 0.016387485 0 0 0</pose>
			<mass>0.589284444</mass>
			<inertia>
				<ixx>0.000545429</ixx>
				<iyy>0.001825441</iyy>
				<izz>0.002054387</izz>
				<iyz>-0.000001187</iyz>
				<ixz>-0.000179602</ixz>
				<ixy>0.000004512</ixy>
			</inertia>
		</inertial>
	</link>
	
	
	<link name="l_hip_yaw_trunnion">
		<pose>-.021 .094 .808 0 0 0</pose>
		<!-- Axis = "z", -->
		<collision name="collision">
			<geometry>
				<cylinder>
					<radius>0.01</radius>
					<length>0.1</length>
				</cylinder>
			</geometry>
		</collision>
		<visual name="visual">
			<geometry>
				<cylinder>
					<radius>0.01</radius>
					<length>0.1</length>
				</cylinder>
			</geometry>
		</visual>
		<inertial>
			<mass>0.1</mass>
			<inertia>
				<ixx>8.5833333333333e-05</ixx>
				<iyy>8.5833333333333e-05</iyy>
				<izz>5e-06</izz>
				<ixy>0</ixy>
				<ixz>0</ixz>
				<iyz>0</iyz>
			</inertia>
		</inertial>
	</link>

	<link name="r_hip_yaw_trunnion">
		<pose>-.021 -.094 .808 0 0 0</pose>
		<!-- Axis = "z", -->
		<collision name="collision">
			<geometry>
				<cylinder>
					<radius>0.01</radius>
					<length>0.1</length>
				</cylinder>
			</geometry>
		</collision>
		<visual name="visual">
			<geometry>
				<cylinder>
					<radius>0.01</radius>
					<length>0.1</length>
				</cylinder>
			</geometry>
		</visual>
		<inertial>
			<mass>0.1</mass>
			<inertia>
				<ixx>8.5833333333333e-05</ixx>
				<iyy>8.5833333333333e-05</iyy>
				<izz>5e-06</izz>
				<ixy>0</ixy>
				<ixz>0</ixz>
				<iyz>0</iyz>
			</inertia>
		</inertial>
	</link>


	<link name="l_hip_pitch_trunnion">
		<pose>-.021 .094 .808 0 0 0</pose>
		<!-- Axis = "y", -->
		<collision name="collision">
			<pose>0 0 0 1.57079632679 0 0</pose>
			<geometry>
				<cylinder>
					<radius>0.01</radius>
					<length>0.1</length>
				</cylinder>
			</geometry>
		</collision>
		<visual name="visual">
			<pose>0 0 0 1.57079632679 0 0</pose>
			<geometry>
				<cylinder>
					<radius>0.01</radius>
					<length>0.1</length>
				</cylinder>
			</geometry>
		</visual>
		<inertial>
			<mass>0.1</mass>
			<inertia>
				<ixx>8.5833333333333e-05</ixx>
				<iyy>5e-06</iyy>
				<izz>8.5833333333333e-05</izz>
				<ixy>0</ixy>
				<ixz>0</ixz>
				<iyz>0</iyz>
			</inertia>
		</inertial>
	</link>

	<link name="r_hip_pitch_trunnion">
		<pose>-.021 -.094 .808 0 0 0</pose>
		<!-- Axis = "y", -->
		<collision name="collision">
			<pose>0 0 0 1.57079632679 0 0</pose>
			<geometry>
				<cylinder>
					<radius>0.01</radius>
					<length>0.1</length>
				</cylinder>
			</geometry>
		</collision>
		<visual name="visual">
			<pose>0 0 0 1.57079632679 0 0</pose>
			<geometry>
				<cylinder>
					<radius>0.01</radius>
					<length>0.1</length>
				</cylinder>
			</geometry>
		</visual>
		<inertial>
			<mass>0.1</mass>
			<inertia>
				<ixx>8.5833333333333e-05</ixx>
				<iyy>5e-06</iyy>
				<izz>8.5833333333333e-05</izz>
				<ixy>0</ixy>
				<ixz>0</ixz>
				<iyz>0</iyz>
			</inertia>
		</inertial>
	</link>


	<link name="l_ankle_pitch_trunnion">
		<pose>-.021 .094 .049 0 0 0</pose>
		<!-- Axis = "y", -->
		<collision name="collision">
			<pose>0 0 0 1.57079632679 0 0</pose>
			<geometry>
				<cylinder>
					<radius>0.01</radius>
					<length>0.1</length>
				</cylinder>
			</geometry>
		</collision>
		<visual name="visual">
			<pose>0 0 0 1.57079632679 0 0</pose>
			<geometry>
				<cylinder>
					<radius>0.01</radius>
					<length>0.1</length>
				</cylinder>
			</geometry>
		</visual>
		<inertial>
			<mass>0.1</mass>
			<inertia>
				<ixx>8.5833333333333e-05</ixx>
				<iyy>5e-06</iyy>
				<izz>8.5833333333333e-05</izz>
				<ixy>0</ixy>
				<ixz>0</ixz>
				<iyz>0</iyz>
			</inertia>
		</inertial>
	</link>

	<link name="r_ankle_pitch_trunnion">
		<pose>-.021 -.094 .049 0 0 0</pose>
		<!-- Axis = "y", -->
		<collision name="collision">
			<pose>0 0 0 1.57079632679 0 0</pose>
			<geometry>
				<cylinder>
					<radius>0.01</radius>
					<length>0.1</length>
				</cylinder>
			</geometry>
		</collision>
		<visual name="visual">
			<pose>0 0 0 1.57079632679 0 0</pose>
			<geometry>
				<cylinder>
					<radius>0.01</radius>
					<length>0.1</length>
				</cylinder>
			</geometry>
		</visual>
		<inertial>
			<mass>0.1</mass>
			<inertia>
				<ixx>8.5833333333333e-05</ixx>
				<iyy>5e-06</iyy>
				<izz>8.5833333333333e-05</izz>
				<ixy>0</ixy>
				<ixz>0</ixz>
				<iyz>0</iyz>
			</inertia>
		</inertial>
	</link>
	
	
	
	<joint name="l_hip_yaw" type="revolute">
		<parent>torso</parent>
		<child>l_hip_yaw_trunnion</child>
		<axis>
			<xyz>0 0 1</xyz>
			<limit>
				<lower>-0.436332313</lower>
				<upper>0.1745329252</upper>
				<effort>300</effort>
				<velocity>12</velocity>
			</limit>
		</axis>
	</joint>
	
	<joint name="r_hip_yaw" type="revolute">
		<parent>torso</parent>
		<child>r_hip_yaw_trunnion</child>
		<axis>
			<xyz>0 0 1</xyz>
			<limit>
				<lower>-0.436332313</lower>
				<upper>0.1745329252</upper>
				<effort>300</effort>
				<velocity>12</velocity>
			</limit>
		</axis>
	</joint>
	
	<joint name="l_hip_roll" type="revolute">
		<parent>l_hip_yaw_trunnion</parent>
		<child>l_hip_pitch_trunnion</child>
		<axis>
			<xyz>1 0 0</xyz>
			<limit>
				<lower>-0.401425728</lower>
				<upper>0.401425728</upper>
				<effort>300</effort>
				<velocity>12</velocity>
			</limit>
		</axis>
	</joint>
	
	<joint name="r_hip_roll" type="revolute">
		<parent>r_hip_yaw_trunnion</parent>
		<child>r_hip_pitch_trunnion</child>
		<axis>
			<xyz>1 0 0</xyz>
			<limit>
				<lower>-0.401425728</lower>
				<upper>0.401425728</upper>
				<effort>300</effort>
				<velocity>12</velocity>
			</limit>
		</axis>
	</joint>
	
	<joint name="l_hip_pitch" type="revolute">
		<!-- thigh pose: -.021 .094 .618 0 0 0 -->
		<!-- desired pose: -.021 .094 .808 0 0 0 -->
		<pose>0 0 .19 0 0 0</pose>
		<parent>l_hip_pitch_trunnion</parent>
		<child>l_thigh</child>
		<axis>
			<xyz>0 1 0</xyz>
			<limit>
				<lower>-0.7853981634</lower>
				<upper>0.7853981634</upper>
				<effort>300</effort>
				<velocity>12</velocity>
			</limit>
		</axis>
	</joint>
	
	<joint name="r_hip_pitch" type="revolute">
		<!-- thigh pose: -.021 -.094 .618 0 0 0 -->
		<!-- desired pose: -.021 -.094 .808 0 0 0 -->
		<pose>0 0 .19 0 0 0</pose>
		<parent>r_hip_pitch_trunnion</parent>
		<child>r_thigh</child>
		<axis>
			<xyz>0 1 0</xyz>
			<limit>
				<lower>-0.7853981634</lower>
				<upper>0.7853981634</upper>
				<effort>300</effort>
				<velocity>12</velocity>
			</limit>
		</axis>
	</joint>
	
	<joint name="l_knee_pitch" type="revolute">
		<!-- shin pose: -.021 .094 .239 0 0 0 -->
		<!-- desired pose: -.021 .094 .429 0 0 0 -->
		<pose>0 0 .19 0 0 0</pose>
		<parent>l_thigh</parent>
		<child>l_shin</child>
		<axis>
			<xyz>0 1 0</xyz>
			<limit>
				<lower>0</lower>
				<upper>1.5707963268</upper>
				<effort>300</effort>
				<velocity>12</velocity>
			</limit>
		</axis>
	</joint>
	
	<joint name="r_knee_pitch" type="revolute">
		<!-- shin pose: -.021 -.094 .239 0 0 0 -->
		<!-- desired pose: -.021 -.094 .429 0 0 0 -->
		<pose>0 0 .19 0 0 0</pose>
		<parent>r_thigh</parent>
		<child>r_shin</child>
		<axis>
			<xyz>0 1 0</xyz>
			<limit>
				<lower>0</lower>
				<upper>1.5707963268</upper>
				<effort>300</effort>
				<velocity>12</velocity>
			</limit>
		</axis>
	</joint>
	
	<joint name="l_ankle_pitch" type="revolute">
		<parent>l_shin</parent>
		<child>l_ankle_pitch_trunnion</child>
		<axis>
			<xyz>0 1 0</xyz>
			<limit>
				<lower>-0.6981317008</lower>
				<upper>0.872664626</upper>
				<effort>300</effort>
				<velocity>12</velocity>
			</limit>
		</axis>
	</joint>
	
	<joint name="r_ankle_pitch" type="revolute">
		<parent>r_shin</parent>
		<child>r_ankle_pitch_trunnion</child>
		<axis>
			<xyz>0 1 0</xyz>
			<limit>
				<lower>-0.6981317008</lower>
				<upper>0.872664626</upper>
				<effort>300</effort>
				<velocity>12</velocity>
			</limit>
		</axis>
	</joint>
	
	<joint name="l_ankle_roll" type="revolute">
		<!-- ankle pose: 0 .094 .003 0 0 0 -->
		<!-- desired pose: -.021 .094 .049 0 0 0 -->
		<pose>-.021 0 .046 0 0 0</pose>
		<parent>l_ankle_pitch_trunnion</parent>
		<child>l_foot</child>
		<axis>
			<xyz>1 0 0</xyz>
			<limit>
				<lower>-0.3490658504</lower>
				<upper>0.3490658504</upper>
				<effort>300</effort>
				<velocity>12</velocity>
			</limit>
		</axis>
		<physics>
			<ode>
				<provide_feedback>1</provide_feedback>
			</ode>
		</physics>
	</joint>
	
	<joint name="r_ankle_roll" type="revolute">
		<!-- ankle pose: 0 -.094 .003 0 0 0 -->
		<!-- desired pose: -.021 -.094 .049 0 0 0 -->
		<pose>-.021 0 .046 0 0 0</pose>
		<parent>r_ankle_pitch_trunnion</parent>
		<child>r_foot</child>
		<axis>
			<xyz>1 0 0</xyz>
			<limit>
				<lower>-0.3490658504</lower>
				<upper>0.3490658504</upper>
				<effort>300</effort>
				<velocity>12</velocity>
			</limit>
		</axis>
		<physics>
			<ode>
				<provide_feedback>1</provide_feedback>
			</ode>
		</physics>
	</joint>
</model>
</sdf>
